<?xml version="1.0" encoding="UTF-8"?>
<!-- Generated by org.testng.reporters.JUnitReportReporter -->
<testsuite hostname="DESKTOP-V415AC9" failures="1" tests="6" name="auth.AuthNegativeTest" time="1.594" errors="0" timestamp="2024-05-06T00:28:41 MSK" skipped="0">
  <testcase classname="auth.AuthNegativeTest" name="checkIncorrectEmailAndCorrectPassword" time="0.253"/>
  <testcase classname="auth.AuthNegativeTest" name="checkEmptyEmailAndCorrectPassword" time="0.198"/>
  <testcase classname="auth.AuthNegativeTest" name="checkCorrectEmailAndEmptyPassword" time="0.241"/>
  <testcase classname="auth.AuthNegativeTest" name="checkIncorrectEmailAndIncorrectPassword" time="0.206"/>
  <testcase classname="auth.AuthNegativeTest" name="checkAppearingAlertTwice" time="0.418">
    <failure message="Alert holder wasn&#039;t closed - probably there were two of them" type="java.lang.AssertionError">
      <![CDATA[java.lang.AssertionError: Alert holder wasn't closed - probably there were two of them
at org.testng.Assert.fail(Assert.java:111)
at auth.AuthNegativeTest.checkAppearingAlertTwice(AuthNegativeTest.java:45)
at java.base/jdk.internal.reflect.NativeMethodAccessorImpl.invoke0(Native Method)
at java.base/jdk.internal.reflect.NativeMethodAccessorImpl.invoke(NativeMethodAccessorImpl.java:64)
at java.base/jdk.internal.reflect.DelegatingMethodAccessorImpl.invoke(DelegatingMethodAccessorImpl.java:43)
at java.base/java.lang.reflect.Method.invoke(Method.java:564)
at org.testng.internal.invokers.MethodInvocationHelper.invokeMethod(MethodInvocationHelper.java:141)
at org.testng.internal.invokers.TestInvoker.invokeMethod(TestInvoker.java:686)
at org.testng.internal.invokers.TestInvoker.invokeTestMethod(TestInvoker.java:230)
at org.testng.internal.invokers.MethodRunner.runInSequence(MethodRunner.java:63)
at org.testng.internal.invokers.TestInvoker$MethodInvocationAgent.invoke(TestInvoker.java:992)
at org.testng.internal.invokers.TestInvoker.invokeTestMethods(TestInvoker.java:203)
at org.testng.internal.invokers.TestMethodWorker.invokeTestMethods(TestMethodWorker.java:154)
at org.testng.internal.invokers.TestMethodWorker.run(TestMethodWorker.java:134)
at java.base/java.util.ArrayList.forEach(ArrayList.java:1511)
at org.testng.TestRunner.privateRun(TestRunner.java:739)
at org.testng.TestRunner.run(TestRunner.java:614)
at org.testng.SuiteRunner.runTest(SuiteRunner.java:421)
at org.testng.SuiteRunner.runSequentially(SuiteRunner.java:413)
at org.testng.SuiteRunner.privateRun(SuiteRunner.java:373)
at org.testng.SuiteRunner.run(SuiteRunner.java:312)
at org.testng.SuiteRunnerWorker.runSuite(SuiteRunnerWorker.java:52)
at org.testng.SuiteRunnerWorker.run(SuiteRunnerWorker.java:95)
at org.testng.TestNG.runSuitesSequentially(TestNG.java:1274)
at org.testng.TestNG.runSuitesLocally(TestNG.java:1208)
at org.testng.TestNG.runSuites(TestNG.java:1112)
at org.testng.TestNG.run(TestNG.java:1079)
at org.apache.maven.surefire.testng.TestNGExecutor.run(TestNGExecutor.java:293)
at org.apache.maven.surefire.testng.TestNGXmlTestSuite.execute(TestNGXmlTestSuite.java:84)
at org.apache.maven.surefire.testng.TestNGProvider.invoke(TestNGProvider.java:91)
at org.apache.maven.surefire.booter.ForkedBooter.invokeProviderInSameClassLoader(ForkedBooter.java:200)
at org.apache.maven.surefire.booter.ForkedBooter.runSuitesInProcess(ForkedBooter.java:153)
at org.apache.maven.surefire.booter.ForkedBooter.main(ForkedBooter.java:103)
]]>
    </failure>
  </testcase> <!-- checkAppearingAlertTwice -->
  <testcase classname="auth.AuthNegativeTest" name="checkCorrectEmailAndIncorrectPassword" time="0.278"/>
</testsuite> <!-- auth.AuthNegativeTest -->
